Workbook

Sheet FEB
A1: TOTAL EXPENSE LIST | J1: AVAILABLE FROM PREVIOUS MONTH: | K1: 5840
A2: PAYMENT REASON | B2: PAYMENT CATEGORY | C2: DATE | D2: PAYMENT AMOUNT | J2: INCOME IN CURRENT MONTH: | K2: 45457
A3: Maa | B3: EMI | C3: =DATE(2022,2,6) -> 44598 | D3: 15000 | J3: INTEREST EARN | K3: 40
A4: SIP | B4: INVEST | C4: =DATE(2022,1,31) -> 44592 | D4: 5000
A5: MOBILE | B5: EMI | C5: =DATE(2022,1,31) -> 44592 | D5: 1300 | J5: TOTAL AVAILABLE: | K5: =SUM(K1:K3) -> 51337
A6: AC | B6: EMI | C6: =DATE(2022,1,31) -> 44592 | D6: 4000
A7: ARGHYA | B7: EMI | C7: =DATE(2022,1,31) -> 44592 | D7: 2000 | J7: AVAILABLE BALANCE: | K7: =K5 - (D26) -> 4319
A8: SMALL PARTY (MOGLAI) | B8: PARTY | C8: =DATE(2022,1,31) -> 44592 | D8: 500
A9: EYE | B9: MEDICAL | C9: =DATE(2022,1,31) -> 44592 | D9: 1500
A10: BABA | B10: PARTY | C10: =DATE(2022,1,31) -> 44592 | D10: 3000
A11: FD | B11: INVEST | C11: =DATE(2022,1,31) -> 44592 | D11: 5000
A12: ELECTRIC BILL | B12: BILL | C12: =DATE(2022,2,1) -> 44593 | D12: 3420
A13: Mobile Recharge (8653640704) | B13: MOBILE BILL | C13: =DATE(2022,2,3) -> 44595 | D13: 99
A14: Hot Gel Pad | B14: MEDICAL | C14: =DATE(2022,2,3) -> 44595 | D14: 179
A15: Rini | B15: PARTY | C15: =DATE(2022,2,6) -> 44598 | D15: 3000
A16: Mobile Recharge (8617414770) | B16: MOBILE BILL | C16: =DATE(2022,2,8) -> 44600 | D16: 99
A17: Mobile Recharge (9434825579) | B17: MOBILE BILL | C17: =DATE(2022,2,8) -> 44600 | D17: 155
A18: Mobile Recharge (9333818130) | B18: MOBILE BILL | C18: =DATE(2022,2,11) -> 44603 | D18: 99
A19: Mobile Recharge (8918405876) | B19: MOBILE BILL | C19: =DATE(2022,2,12) -> 44604 | D19: 155
A20: Thesis Project expense | B20: EDUCATION | C20: =DATE(2022,2,12) -> 44604 | D20: 1000
A21: WIFI | B21: BILL | C21: =DATE(2022,2,13) -> 44605 | D21: 1357
A22: Mobile Recharge (6296963476) | B22: MOBILE BILL | C22: =DATE(2022,2,20) -> 44612 | D22: 155
C26: TOTAL EXPENSE | D26: =SUM(D3:D24) -> 47018
A28: PENDING
A29: PAYMENT REASON | B29: PAYMENT CATEGORY | D29: PAYMENT AMOUNT
C38: PENDING EXPENSE | D38: =SUM(D21:D36) -> 48530

Sheet MAR
A1: TOTAL EXPENSE LIST | G1: AVAILABLE FROM PREVIOUS MONTH: | H1: =FEB!K7 -> 4319
A2: PAYMENT REASON | B2: PAYMENT CATEGORY | C2: DATE | D2: PAYMENT AMOUNT | G2: INCOME IN CURRENT MONTH: | H2: =40000+1357 -> 41357
A3: Maa | B3: EMI | C3: =DATE(2022, 2, 26) -> 44618 | D3: 12000 | G3: Savings add | H3: 18000
A4: Arghya (Trade mil & screen) | B4: EMI | C4: =DATE(2022, 2, 27) -> 44619 | D4: 2500 | G4: Ticket Pending | H4: 1300
A5: Arghya (Scooty) | B5: EMI | C5: =DATE(2022, 2, 27) -> 44619 | D5: 2860 | G5: TOTAL AVAILABLE: | H5: =H1 + H2 + H3 -> 63676
A6: Electric bill | B6: BILL | C6: =DATE(2022, 2, 27) -> 44619 | D6: 3330 | J6: Expected Avail. Bal: | K6: =H7 - D47 -> 20232.5
A7: SIP | B7: INVESTMENT | C7: 44619 | D7: 4700 | G7: AVAILABLE BALANCE: | H7: =H5 - (D27) -> 20232.5
A8: FD | B8: INVESTMENT | C8: 44619 | D8: 5000
A9: MOBILE | B9: EMI | C9: 44620 | D9: 1300
A10: Cook | B10: FAMILY | C10: 44620 | D10: 1000
A11: iAloy HW | B11: PROJECT | C11: 44620 | D11: 3000
A12: Cash | B12: PERSONAL | C12: 44620 | D12: 500
A13: Mobile Recharge (8653640704) | B13: MOBILE BILL | C13: =DATE(2022,3,3) -> 44623 | D13: 99
A14: Mobile Recharge (8617414770) | B14: MOBILE BILL | C14: =DATE(2022,3,10) -> 44630 | D14: 155 | G14: BERHAMPORE TRIP
A15: Mobile Recharge (9046266900) | B15: MOBILE BILL | C15: =DATE(2022,3,10) -> 44630 | D15: 99 | G15: Train ticket(knj-bpc) | H15: =DATE(2022,3,11) -> 44631 | I15: 142 | K15: D
A16: Mobile Recharge (8918405876) | B16: MOBILE BILL | C16: =DATE(2022,3,10) -> 44630 | D16: 155 | G16: Train ticket(bpc-knj) | H16: =DATE(2022,3,11) -> 44631 | I16: 50 | K16: D
A17: Mobile Recharge (9333818130) | B17: MOBILE BILL | C17: =DATE(2022,3,10) -> 44630 | D17: 99 | G17: Lunch | I17: 1924 | K17: A
A18: WiFi | B18: BILL | C18: =DATE(2022,3,15) -> 44635 | D18: 1357 | G18: Dinner | I18: 1800 | K18: D
A19: Train Ticket(Puri) | C19: =DATE(2022,3,12) -> 44632 | D19: 1227 | G19: Toto night | I19: 80 | J19: Arghya | K19: A
A20: Train Ticket(BPC) | B20: Berhampore | D20: 142.5 | G20: Canteene | I20: 500 | K20: D
A21: Hotpot | B21: Berhampore | D21: 650 | G21: Guest room | I21: 400 | K21: A
A22: Cash | D22: 1000 | G22: Lunch | I22: 800 | J22: Arghya | K22: A
A23: Table Fan | C23: =DATE(2022,3,19) -> 44639 | D23: 900 | G23: Blue wave | I23: 356
A24: Arghya | B24: Berhampore | C24: =DATE(2022,3,31) -> 44651 | D24: 735
A25: HotStar recharge | B25: BILL | C25: =DATE(2022,3,27) -> 44647 | D25: 635
C27: TOTAL EXPENSE | D27: =SUM(D3:D25) -> 43443.5 | L27: 2292
G28: TOTAL | I28: =sum(I15:I26) -> 6052 | L28: 3760 | M28: 236
A30: PENDING | I30: =(I28/2) -> 3026
A31: PAYMENT REASON | B31: PAYMENT CATEGORY | D31: PAYMENT AMOUNT | I31: =(I30+650) -> 3676
C47: PENDING EXPENSE | D47: =SUM(D32:D45) -> 0

Sheet APR
A1: TOTAL EXPENSE LIST | G1: AVAILABLE FROM PREVIOUS MONTH: | H1: =MAR!H7 -> 20232.5
A2: PAYMENT REASON | B2: PAYMENT CATEGORY | C2: DATE | D2: PAYMENT AMOUNT | G2: INCOME IN CURRENT MONTH: | H2: 41357
A3: Electronics | B3: TECH | C3: =DATE(2022,3,29) -> 44649 | D3: 1144.84 | G3: Interest Earn | H3: 81
A4: Mobile Recharge (8653640704) | B4: MOBILE BILL | C4: =DATE(2022,3,30) -> 44650 | D4: 99
A5: Arghya (Scooty) | B5: EMI | C5: =DATE(2022,3,31) -> 44651 | D5: 2350
A6: SIP | B6: INVESTMENT | C6: =DATE(2022,3,31) -> 44651 | D6: 5000 | G6: TOTAL AVAILABLE: | H6: =SUM(H1:H4) -> 61670.5
A7: FD | B7: INVESTMENT | C7: =DATE(2022,3,31) -> 44651 | D7: 5000
A8: Electric bill | B8: BILL | C8: =DATE(2022,3,31) -> 44651 | D8: 3318 | G8: AVAILABLE BALANCE: | H8: =H6 - (D31) -> 17960.66
A9: Fan | B9: FAMILY | C9: =DATE(2022,3,31) -> 44651 | D9: 1337 | G9: Expected Avail. Bal: | H9: =H8 - D54 -> 17310.66
A10: Damma medicine | B10: FAMILY | C10: =DATE(2022,4,10) -> 44661 | D10: 2000
A11: MOBILE | B11: EMI | C11: =DATE(2022,4,1) -> 44652 | D11: 1300
A12: MAA | B12: EMI | C12: =DATE(2022,4,1) -> 44652 | D12: 13000
A13: Cook | B13: FAMILY | C13: =DATE(2022,4,1) -> 44652 | D13: 1000
A14: In Hand | B14: PERSONAL | C14: =DATE(2022,4,1) -> 44652 | D14: 1400
A15: Shopping | B15: PERSONAL | C15: =DATE(2022,4,2) -> 44653 | D15: 3478
A16: Mobile Recharge (8918405876) | B16: MOBILE BILL | C16: =DATE(2022,3,30) -> 44650 | D16: 155
A17: Mobile Recharge (8617414770) | B17: MOBILE BILL | C17: =DATE(2022,3,30) -> 44650 | D17: 155
A18: Mobile Recharge (9333818130) | B18: MOBILE BILL | C18: =DATE(2022,4,11) -> 44662 | D18: 99
A19: WiFi | B19: BILL | C19: =DATE(2022,4,14) -> 44665 | D19: 1357
A20: HeadPhone | B20: PERSONAL | C20: =DATE(2022,4,11) -> 44662 | D20: 180
A21: Light | B21: FAMILY | C21: =DATE(2022,4,18) -> 44669 | D21: 330
A22: Medical form fillup | B22: RINI | C22: =DATE(2022,4,27) -> 44678 | D22: 900
A23: Mobile Recharge (8653640704) | B23: MOBILE BILL | C23: =DATE(2022,4,26) -> 44677 | D23: 99
A24: Misc. | D24: 8
C31: TOTAL EXPENSE | D31: =SUM(D3:D29) -> 43709.84
A34: PENDING
A35: PAYMENT REASON | B35: PAYMENT CATEGORY | D35: PAYMENT AMOUNT
A38: Arghya (Screen) | B38: EMI | D38: 650
C54: PENDING EXPENSE | D54: =SUM(D36:D52) -> 650

Sheet MAY
A1: TOTAL EXPENSE LIST | J1: AVAILABLE FROM PREVIOUS MONTH: | K1: =APR!H8 -> 17960.66
A2: PAYMENT REASON | B2: PAYMENT CATEGORY | C2: DATE | D2: PAYMENT AMOUNT | J2: INCOME IN CURRENT MONTH: | K2: 40000
A3: Rini Unacademy | B3: EDUCATION | C3: =DATE(2022,4,29) -> 44680 | D3: 239 | J3: TOTAL AVAILABLE: | K3: =K1 + K2 -> 57960.66
A4: Arghya (Scooty) | B4: EMI | C4: =DATE(2022,4,30) -> 44681 | D4: 2350
A5: Bangalore | B5: HOME RENT | C5: =DATE(2022,4,30) -> 44681 | D5: 20000 | J5: AVAILABLE BALANCE: | K5: =K3 - (D26) -> 2326.62
A6: SIP | B6: INVESTMENT | C6: =DATE(2022,4,30) -> 44681 | D6: 5000 | J6: Expected Avail. Bal: | K6: =K5 - D48 -> -56836.17
A7: FD | B7: INVESTMENT | C7: =DATE(2022,4,30) -> 44681 | D7: 5000
A8: Electric bill | B8: BILL | C8: =DATE(2022,4,30) -> 44681 | D8: 4069
A9: Extra SIP | B9: TEMP | C9: =DATE(2022,4,30) -> 44681 | D9: 500
A10: MAA | B10: EMI | C10: =DATE(2022,5,1) -> 44682 | D10: 8000
A11: Cook | B11: FAMILY | C11: =DATE(2022,5,1) -> 44682 | D11: 1000
A12: In Hand | B12: PERSONAL | C12: =DATE(2022,5,1) -> 44682 | D12: =200+380+1000 -> 1580
A13: Mother's Hut | B13: FAMILY | C13: =DATE(2022,4,30) -> 44681 | D13: 1900
A14: Berhampore | B14: SOCIAL | C14: =DATE(2022,5,7) -> 44688 | D14: =(842+860+260+500) -> 2462
A15: Misc | D15: 5.29
A16: WiFi | B16: BILL | C16: =DATE(2022,5,14) -> 44695 | D16: 1357
A17: Mobile recharge(8918405876) | B17: BILL | D17: 155
A18: Mobile recharge(8653640704) | B18: BILL | D18: 99
A19: Mobile recharge(8918405876) | B19: BILL | D19: 155
A20: TEMP | D20: =(75+126.8+478.95+155+155+99+50+240)-1000 -> 379.75
A21: Mobile recharge(9434825579) | B21: BILL | D21: 607
A22: Cinema | D22: 130
A23: Misc | D23: 646
C26: TOTAL EXPENSE | D26: =SUM(D3:D24) -> 55634.04
A29: PENDING
A30: PAYMENT REASON | B30: PAYMENT CATEGORY | D30: PAYMENT AMOUNT
C48: PENDING EXPENSE | D48: =SUM(D16:D45) -> 59162.79

Sheet JUN
A1: TOTAL EXPENSE LIST | J1: AVAILABLE FROM PREVIOUS MONTH: | K1: =MAY!K5 -> 2326.62
A2: PAYMENT REASON | B2: PAYMENT CATEGORY | C2: DATE | D2: PAYMENT AMOUNT | J2: INCOME IN CURRENT MONTH: | K2: 41357
A3: Arghya (Scooty) | B3: EMI | D3: 2350 | J3: TOTAL AVAILABLE: | K3: =K1 + K2 -> 43683.62
A4: Electric bill | B4: BILL | D4: 4106
A5: In Hand | B5: PERSONAL | D5: 500 | J5: AVAILABLE BALANCE: | K5: =K3 - (D26) -> 2967.12
A6: Bangalore | B6: HOME RENT | C6: =DATE(2022,4,30) -> 44681 | D6: 6000
A7: MAA | B7: EMI | D7: 8000
A8: Cook | B8: FAMILY | D8: 1000
A9: SIP | B9: INVESTMENT | D9: 5000
A11: Conference | B11: EDUCATION | D11: 4612.5
A12: Water Purifier | B12: FAMILY | D12: 3300
A13: Rini HS Review | D13: 900
A14: Mislenous | D14: 4948
C26: TOTAL EXPENSE | D26: =SUM(D3:D24) -> 40716.5
A29: PENDING
A30: PAYMENT REASON | B30: PAYMENT CATEGORY | D30: PAYMENT AMOUNT
A33: WiFi | B33: BILL | D33: 1357
A34: MOBILE RECHARGE | B34: BILL | D34: 607
A37: FD | B37: INVESTMENT | D37: 5000
C48: PENDING EXPENSE | D48: =SUM(D7:D46) -> 75441
A53: Arghya (Screen) | B53: EMI | D53: 650

Sheet JUL
A1: TOTAL EXPENSE LIST | J1: AVAILABLE FROM PREVIOUS MONTH: | K1: =JUN!K5 -> 2967.12
A2: PAYMENT REASON | B2: PAYMENT CATEGORY | C2: DATE | D2: PAYMENT AMOUNT | J2: INCOME IN CURRENT MONTH: | K2: 40000
A3: SSD | D3: 1300 | J3: KAKA | K3: 15000
A4: Arghya (Scooty) | B4: EMI | D4: 2350 | J4: TOTAL AVAILABLE: | K4: =K1 + K2 + K3 -> 57967.12
A5: Bangalore | B5: HOME RENT | D5: 6000
A6: Electric bill | B6: BILL | D6: 4103 | J6: AVAILABLE BALANCE: | K6: =K4 - (D31) -> 34137.67
A7: SIP | B7: INVESTMENT | D7: 2000 | J7: EXP AVAILABLE BALANCE: | K7: =K4 - (D32) - D55 -> 48658.12
A8: CASH | B8: TEMP | D8: =(422.5 + 1509.65 + 1034.3 + 25) - 570 -> 2421.45
A9: Arghya (Flight) | B9: BILL | D9: 3000
A10: Mobile recharge(8918405876) | B10: BILL | D10: 155
A11: SIP | B11: TEMP | D11: 2500
C31: TOTAL EXPENSE | D31: =SUM(D3:D29) -> 23829.45
A34: PENDING
A35: PAYMENT REASON | B35: PAYMENT CATEGORY | D35: PAYMENT AMOUNT
A38: In Hand | B38: PERSONAL | D38: 500
A40: MAA | B40: EMI | D40: 6000
A41: Cook | B41: FAMILY | D41: 1000
A43: WiFi | B43: BILL | D43: 1357
A44: MOBILE RECHARGE | B44: BILL | D44: =607 - (155) -> 452
A46: Kurukshetra
C55: PENDING EXPENSE | D55: =SUM(D36:D53) -> 9309

Sheet AUG
A1: TOTAL EXPENSE LIST | J1: AVAILABLE FROM PREVIOUS MONTH: | K1: 1530
A2: PAYMENT REASON | B2: PAYMENT CATEGORY | C2: DATE | D2: PAYMENT AMOUNT | J2: INCOME IN CURRENT MONTH: | K2: =(193737 + 1357) -> 195094
A3: Pujo | B3: PUJO | C3: =DATE(2022, 7, 27) -> 44769 | D3: 15000 | J3: TOTAL AVAILABLE: | K3: =K1 + K2 -> 196624
A4: Cash | B4: CASH | C4: =DATE(2022, 7, 27) -> 44769 | D4: 500
A5: Chawala | B5: SOCIAL | C5: =DATE(2022, 7, 27) -> 44769 | D5: =(398+149) -> 547 | J5: CURRENT AVAILABLE BALANCE: | K5: =K3 - (D43) -> 89488
A6: Flat rent | B6: BANGALORE | C6: =DATE(2022, 7, 29) -> 44771 | D6: 10500 | J6: EXPECTED AVAILABLE BALANCE: | K6: =K5 - D62 + SUM(D19:D21) -> -124657
A7: Arghya (Scooty) | B7: EMI | C7: =DATE(2022, 7, 29) -> 44771 | D7: 2350
A8: Arghya | B8: PENDING | C8: =DATE(2022, 7, 29) -> 44771 | D8: =(5000+2000+1300) -> 8300
A9: Electric bill | B9: BILL | C9: =DATE(2022, 7, 29) -> 44771 | D9: 5763
A10: SIP | B10: INVESTMENT | C10: =DATE(2022, 7, 29) -> 44771 | D10: 5000
A11: FD | B11: INVESTMENT | C11: =DATE(2022, 7, 29) -> 44771 | D11: 10000
A12: Mobile recharge(8918405876) | B12: BILL | C12: =DATE(2022, 7, 29) -> 44771 | D12: 155
A13: Karkhana repair | B13: HOME | C13: =DATE(2022, 7, 29) -> 44771 | D13: 5800
A14: Mobile recharge(9333818130) | B14: BILL | C14: =DATE(2022, 7, 30) -> 44772 | D14: 99
A15: Flight Booking | B15: BANGALORE | C15: =DATE(2022, 7, 31) -> 44773 | D15: 13502
A16: Jeevansathi.com | B16: SUBSCRIPTION | C16: =DATE(2022, 7, 31) -> 44773 | D16: 692
A17: MAA | B17: EMI | C17: =DATE(2022, 7, 31) -> 44773 | D17: 16000
A18: Cook | B18: FAMILY | C18: =DATE(2022, 7, 31) -> 44773 | D18: 3000
A19: Pujo | B19: PUJO | C19: =DATE(2022, 7, 27) -> 44769 | D19: 7500
A20: Foldable wordrobe | B20: FAMILY | C20: =DATE(2022, 8, 1) -> 44774 | D20: 1279
A21: Fuchka | B21: FAMILY | D21: =(210+60+80) -> 350
A22: Cha Khor | B22: FAMILY | C22: =DATE(2022, 8, 1) -> 44774 | D22: 200
A23: Mobile recharge(9046266900) | B23: BILL | C23: =DATE(2022, 7, 30) -> 44772 | D23: 99
A24: Mobile recharge(9333818130) | B24: BILL | C24: =DATE(2022, 8, 7) -> 44780 | D24: 100
A25: Extra Paytm | B25: BILL | C25: =DATE(2022, 8, 7) -> 44780 | D25: 400
C43: TOTAL EXPENSE | D43: =SUM(D3:D40) -> 107136
A46: PENDING
A47: PAYMENT REASON | B47: PAYMENT CATEGORY | D47: PAYMENT AMOUNT
A50: WiFi | B50: BILL | D50: 1357
A51: MOBILE RECHARGE | B51: BILL | D51: =(607 - (D12 + D14)) -> 353
A52: Technical expenses | B52: TECHNICAL | D52: 8000
A54: Pujo | B54: PUJO | D54: =(100000 - (D3 + D19)) -> 77500
C62: PENDING EXPENSE | D62: =SUM(D17:D60) -> 223274
A66: Arghya | B66: PENDING | D66: =(30000) -> 30000
A67: Kaka | B67: PENDING | D67: =(15000+10000+5000) -> 30000

Sheet SEP
A1: TOTAL EXPENSE LIST | J1: AVAILABLE FROM PREVIOUS MONTH: | K1: 1530
A2: PAYMENT REASON | B2: PAYMENT CATEGORY | C2: DATE | D2: PAYMENT AMOUNT | J2: INCOME IN CURRENT MONTH: | K2: =(193737 + 1357) -> 195094
A3: Pujo | B3: PUJO | C3: =DATE(2022, 7, 27) -> 44769 | D3: 15000 | J3: TOTAL AVAILABLE: | K3: =K1 + K2 -> 196624
A4: Cash | B4: CASH | C4: =DATE(2022, 7, 27) -> 44769 | D4: 500
A5: Chawala | B5: SOCIAL | C5: =DATE(2022, 7, 27) -> 44769 | D5: =(398+149) -> 547 | J5: CURRENT AVAILABLE BALANCE: | K5: =K3 - (D34) -> 118209
A6: Flat rent | B6: BANGALORE | C6: =DATE(2022, 7, 29) -> 44771 | D6: 10500 | J6: EXPECTED AVAILABLE BALANCE: | K6: =K5 - D59 + SUM(D13:D16) -> 17900
A7: Arghya (Scooty) | B7: EMI | C7: =DATE(2022, 7, 29) -> 44771 | D7: 2350
A8: Arghya | B8: PENDING | C8: =DATE(2022, 7, 29) -> 44771 | D8: =(5000+2000+1300) -> 8300
A9: Electric bill | B9: BILL | C9: =DATE(2022, 7, 29) -> 44771 | D9: 5763
A10: SIP | B10: INVESTMENT | C10: =DATE(2022, 7, 29) -> 44771 | D10: 5000
A11: FD | B11: INVESTMENT | C11: =DATE(2022, 7, 29) -> 44771 | D11: 10000
A12: Mobile recharge(8918405876) | B12: BILL | C12: =DATE(2022, 7, 29) -> 44771 | D12: 155
A13: SIP (KAKA) | B13: TEMP | C13: =DATE(2022, 7, 29) -> 44771 | D13: =(2500) -> 2500
A14: TV | B14: TEMP | C14: =DATE(2022, 7, 29) -> 44771 | D14: =(1000) -> 1000
A15: Gold loan | B15: TEMP | C15: =DATE(2022, 7, 29) -> 44771 | D15: 4000
A16: Unacademy | B16: TEMP | C16: =DATE(2022, 7, 29) -> 44771 | D16: 3000
A17: Karkhana repair | B17: HOME | C17: =DATE(2022, 7, 29) -> 44771 | D17: 5800
A18: Arghya (Setup) | B18: EMI | C18: =DATE(2022, 8, 27) -> 44800 | D18: 4000
C34: TOTAL EXPENSE | D34: =SUM(D3:D32) -> 78415
A37: PENDING
A38: PAYMENT REASON | B38: PAYMENT CATEGORY | D38: PAYMENT AMOUNT
A39: MAA | B39: EMI | D39: 15000
A40: Cook | B40: FAMILY | D40: 1000
A41: WiFi | B41: BILL | D41: 1357
A42: MOBILE RECHARGE | B42: BILL | D42: =(607 - (D12)) -> 452
A43: Technical expenses | B43: TECHNICAL | D43: 8000
A45: Pujo | B45: PUJO | D45: =(100000 - D3) -> 85000
C59: PENDING EXPENSE | D59: =SUM(D39:D57) -> 110809
A63: Arghya | B63: PENDING | D63: =(30000) -> 30000
A64: Kaka | B64: PENDING | D64: =(15000+10000+5000) -> 30000

Sheet OCT
A1: TOTAL EXPENSE LIST | J1: AVAILABLE FROM PREVIOUS MONTH: | K1: 2185
A2: PAYMENT REASON | B2: PAYMENT CATEGORY | C2: DATE | D2: PAYMENT AMOUNT | J2: INCOME IN CURRENT MONTH: | K2: 87045
A3: MAA | B3: EMI | C3: =DATE(2022, 9, 29) -> 44833 | D3: 500 | J3: TOTAL AVAILABLE: | K3: =K1 + K2 -> 89230
A4: PW-Rini | B4: EDUCATION | C4: =DATE(2022, 9, 29) -> 44833 | D4: 4149
A5: Ice-Cream | B5: FAMILY | C5: =DATE(2022, 9, 28) -> 44832 | D5: 220 | J5: CURRENT AVAILABLE BALANCE: | K5: =K3 - (D34) -> 1472
A6: Flat rent | B6: BANGALORE | C6: =DATE(2022, 9, 30) -> 44834 | D6: 7500
A7: Arghya (Scooty) | B7: EMI | C7: =DATE(2022, 9, 30) -> 44834 | D7: 2350
A8: UTI-SIP | B8: SAVINGS | C8: =DATE(2022, 9, 30) -> 44834 | D8: 2000 | J8: Return from KAKA | K8: =(D11 + D16 ) -> 5147
A9: SIP | B9: SAVINGS | C9: =DATE(2022, 9, 30) -> 44834 | D9: 3000
A10: SAVINGS | B10: SAVINGS | C10: =DATE(2022, 9, 30) -> 44834 | D10: 10000 | J10: EXPECTED AVAILABLE BALANCE: | K10: =K5 - D59 + K8 -> 928
A11: SIP-KAKA | B11: TEMP | C11: =DATE(2022, 9, 30) -> 44834 | D11: 2500
A12: Jogodhatri Pujo | B12: PUJO | C12: =DATE(2022, 9, 30) -> 44834 | D12: 13000 | E12: Transfered to Joint A/C
A13: Kali Pujo | B13: PUJO | C13: =DATE(2022, 9, 30) -> 44834 | D13: 3000
A14: Electricity | B14: FAMILY | C14: =DATE(2022, 9, 30) -> 44834 | D14: 5763 | J14: Pujo Expense estimate | K14: =D12 -> 13000
A15: Mobile (EMI) | B15: EMI | C15: =DATE(2022, 10, 2) -> 44836 | D15: 3648
A16: Rini | B16: TEMP | C16: =DATE(2022, 10, 2) -> 44836 | D16: 2647 | J16: PUJO EXPENSES
A17: Chawala | B17: Social | C17: =DATE(2022, 9, 30) -> 44834 | D17: 248 | J17: Sajh advance | K17: =DATE(2022, 10, 6) -> 44840 | L17: 2001
A18: Mobile Recharge(7908760756) | B18: BILL | C18: =DATE(2022, 10, 5) -> 44839 | D18: 155 | J18: Electrical expenses | L18: 2500
A19: Mobile Recharge(8653640704) | B19: BILL | C19: =DATE(2022, 10, 5) -> 44839 | D19: 99
A20: Mobile Recharge(9333818130) | B20: BILL | C20: =DATE(2022, 10, 5) -> 44839 | D20: 99
A21: Cash | B21: PERSONAL | C21: =DATE(2022, 10, 2) -> 44836 | D21: 1500
A22: Paytm | B22: PERSONAL | C22: =DATE(2022, 10, 5) -> 44839 | D22: 100
A23: MAA | B23: EMI | C23: =DATE(2022, 10, 5) -> 44839 | D23: 12000
A24: Cook | B24: FAMILY | C24: =DATE(2022, 10, 5) -> 44839 | D24: 1000
A25: Flight Bangalore | B25: TRAVEL | C25: =DATE(2022, 10, 6) -> 44840 | D25: 6545
A26: Train KNJ_SDAH | B26: TRAVEL | C26: =DATE(2022, 10, 6) -> 44840 | D26: 141
A27: Barir Kaj | B27: FAMILY | C27: =DATE(2022, 10, 11) -> 44845 | D27: 1610
A28: Transfer to PayTM | B28: PERSONAL | C28: =DATE(2022, 10, 8) -> 44842 | D28: 452 | J28: Total Pujo Expenses | L28: =SUM(L17:L26) -> 4501
A29: Chowmin | B29: FAMILY | C29: =DATE(2022, 10, 10) -> 44844 | D29: 318 | J29: Remaining in Hand | L29: =K14-L28 -> 8499
A30: BhaiPhota gift | B30: FAMILY | C30: =DATE(2022, 10, 25) -> 44859 | D30: 700
A31: Food & Icecream | B31: PERSONAL | C31: =DATE(2022, 10, 25) -> 44859 | D31: 289
A32: Mislenious | D32: 2225
C34: TOTAL EXPENSE | D34: =SUM(D3:D32) -> 87758
A37: PENDING
A38: PAYMENT REASON | B38: PAYMENT CATEGORY | D38: PAYMENT AMOUNT
A39: WiFi | B39: BILL | D39: 1357
A40: MOBILE RECHARGE | B40: BILL | D40: =(762 - (D18 + D19 + D20)) -> 409
A41: Technical expenses | B41: TECHNICAL | D41: 2000
A42: Arghya (EMI Chair) | B42: EMI | D42: 1925
C59: PENDING EXPENSE | D59: =SUM(D38:D57) -> 5691
...

Sheet NOV
A1: TOTAL EXPENSE LIST | J1: AVAILABLE FROM PREVIOUS MONTH: | K1: =OCT!K1 -> 2185
A2: PAYMENT REASON | B2: PAYMENT CATEGORY | C2: DATE | D2: PAYMENT AMOUNT | J2: INCOME IN CURRENT MONTH: | K2: 134092
A3: SIP | B3: SAVINGS | C3: =DATE(2022, 10, 28) -> 44862 | D3: 3000 | J3: NLC Return | K3: 144
A4: SAVINGS | B4: SAVINGS | C4: =DATE(2022, 10, 28) -> 44862 | D4: 34000 | J4: TOTAL AVAILABLE: | K4: =K1 + K2 + K3 -> 136421
A5: SIP-KAKA | B5: TEMP | C5: =DATE(2022, 10, 28) -> 44862 | D5: 2500 | J5: CURRENT AVAILABLE BALANCE: | K5: =K4 - (D34) -> 2917
A6: Electricity | B6: FAMILY | C6: =DATE(2022, 10, 28) -> 44862 | D6: 5186
A7: MAA (UCO) | B7: EMI | C7: =DATE(2022, 10, 28) -> 44862 | D7: 500
A8: Jogodhatri Pujo | B8: PUJO | C8: =DATE(2022, 10, 28) -> 44862 | D8: 12000 | E8: Transfered to Joint A/C
A9: UTI-SIP | B9: SAVINGS | C9: =DATE(2022, 10, 28) -> 44862 | D9: 2000
A10: Arghya (Scooty) | B10: EMI | C10: =DATE(2022, 10, 28) -> 44862 | D10: 2350 | J10: EXPECTED AVAILABLE BALANCE: | K10: =K5 - D68 + (D52 + D53 + D5) -> 5417
A11: Flat rent | B11: BANGALORE | C11: =DATE(2022, 10, 28) -> 44862 | D11: 7500
A12: Arghya (EMI Chair) | B12: EMI | C12: =DATE(2022, 10, 28) -> 44862 | D12: 1925
A13: FlipKart Paylater | B13: PURCHASE | C13: =DATE(2022, 10, 28) -> 44862 | D13: 1799
A14: MAA | B14: EMI | C14: =DATE(2022, 10, 28) -> 44862 | D14: 500 | J14: Pujo amount | L14: =D8 + OCT!K14 -> 25000
A15: Pujo Shopping | B15: FAMILY | C15: =DATE(2022, 10, 28) -> 44862 | D15: 5000
A16: Puchu Birthday | B16: SOCIAL | C16: =DATE(2022, 10, 29) -> 44863 | D16: 700 | J16: JOGODHATRI PUJO EXPENSES
A17: Cash | B17: PERSONAL | C17: =DATE(2022, 10, 29) -> 44863 | D17: 3350 | J17: Sajh advance | K17: =DATE(2022, 10, 6) -> 44840 | L17: 2001
A18: MAA | B18: EMI | C18: INSTANT | D18: 12000 | J18: Electrical expenses | L18: 2550
A19: Cook | B19: FAMILY | C19: INSTANT | D19: 1000 | J19: Sajh advance (Chota) | L19: 2500
A20: Flat electricity | B20: BANGALORE | D20: 300 | J20: Thakur | L20: 15000
A21: MOBILE RECHARGE | B21: BILL | D21: =762 -> 762
A22: Mobile (EMI) | B22: EMI | C22: INSTANT | D22: 3278
A23: Puri Trip | B23: FAMILY | D23: 8000
A24: Jogodhatri Pujo | B24: FAMILY | D24: 4000
A25: Technical expenses | B25: TECHNICAL | D25: 2000
A26: WiFi | D26: 1357
A27: Misclenious | D27: 18497
J28: Total Pujo Expenses | L28: =SUM(L17:L26) -> 22051
J29: Remaining in Hand | L29: =L14-L28 -> 2949
C34: TOTAL EXPENSE | D34: =SUM(D3:D32) -> 133504
A37: PENDING
A38: PAYMENT REASON | B38: PAYMENT CATEGORY | D38: PAYMENT AMOUNT
C68: PENDING EXPENSE | D68: =SUM(D38:D66) -> 0
A73: Kaka | B73: PENDING | D73: 30000

Sheet DEC
A1: TOTAL EXPENSE LIST | J1: AVAILABLE FROM PREVIOUS MONTH: | K1: =NOV!K5 -> 2917
A2: PAYMENT REASON | B2: PAYMENT CATEGORY | C2: DATE | D2: PAYMENT AMOUNT | J2: INCOME IN CURRENT MONTH: | K2: 85098
A3: SAVINGS | B3: SAVINGS | C3: =DATE(2022, 11, 28) -> 44893 | D3: 10000
A4: Personal | B4: PERSONAL | C4: =DATE(2022, 11, 28) -> 44893 | D4: 5000 | J4: TOTAL AVAILABLE: | K4: =K1 + K2 + K3 -> 88015
A5: UTI-SIP | B5: SAVINGS | C5: =DATE(2022, 11, 28) -> 44893 | D5: 1000 | J5: CURRENT AVAILABLE BALANCE: | K5: =K4 - (D27) -> 7419
A6: Flat rent | B6: BANGALORE | C6: =DATE(2022, 11, 28) -> 44893 | D6: 7500
A7: Arghya (Scooty) | B7: EMI | C7: =DATE(2022, 11, 28) -> 44893 | D7: 2350
A8: Arghya (EMI Chair) | B8: EMI | C8: =DATE(2022, 11, 28) -> 44893 | D8: 1925
A9: SIP-KAKA | B9: TEMP | C9: =DATE(2022, 11, 28) -> 44893 | D9: 2500
A10: SIP | B10: SAVINGS | C10: =DATE(2022, 11, 28) -> 44893 | D10: 3000 | J10: EXPECTED AVAILABLE BALANCE: | K10: =K5 - D62 -> 7419
A11: Electricity | B11: FAMILY | C11: =DATE(2022, 11, 28) -> 44893 | D11: 5185
A12: MAA | B12: EMI | C12: =DATE(2022, 11, 28) -> 44893 | D12: 12000
A13: Cook | B13: FAMILY | C13: =DATE(2022, 11, 28) -> 44893 | D13: 1000
A14: Mobile (EMI) | B14: EMI | C14: =DATE(2022, 12, 1) -> 44896 | D14: 3278
A15: MAA (UCO) | B15: EMI | C15: =DATE(2022, 11, 28) -> 44893 | D15: 500
A16: Bangalore Train | B16: FAMILY | C16: =DATE(2022, 11, 28) -> 44893 | D16: =(3312+3313) -> 6625
A17: Office Expense | B17: SOCIAL | C17: =DATE(2022, 11, 30) -> 44895 | D17: 250
A18: USB-C to HDMI adapter | B18: PERSONAL | C18: =DATE(2022, 11, 29) -> 44894 | D18: 1380
A19: MOBILE RECHARGE | B19: BILL | D19: =762 -> 762
A20: Flat electricity | B20: BANGALORE | D20: 221
A21: Personal | B21: PERSONAL | D21: 15000
A22: Technical Expenses | B22: PERSONAL | D22: =(2000 - D18) -> 620
A23: MAA (UCO) | B23: EMI | C23: =DATE(2022, 12, 28) -> 44923 | D23: 500
C27: TOTAL EXPENSE | D27: =SUM(D3:D25) -> 80596
A31: PENDING
A32: PAYMENT REASON | B32: PAYMENT CATEGORY | D32: PAYMENT AMOUNT
C62: PENDING EXPENSE | D62: =SUM(D32:D60) -> 0
A67: Kaka | B67: PENDING | D67: 30000

Sheet JAN23
A1: TOTAL EXPENSE LIST | J1: AVAILABLE FROM PREVIOUS MONTH: | K1: 7300
A2: PAYMENT REASON | B2: PAYMENT CATEGORY | C2: DATE | D2: PAYMENT AMOUNT | J2: INCOME IN CURRENT MONTH: | K2: 73164
A3: Mobile (EMI) | B3: EMI | C3: =DATE(2023, 1, 1) -> 44927 | D3: 3278
A4: Electricity | B4: FAMILY | C4: =DATE(2022, 12, 30) -> 44925 | D4: 5186 | J4: TOTAL AVAILABLE: | K4: =K1 + K2 + K3 -> 80464
A5: Mobile Recharge (Rini) | B5: BILL | C5: =DATE(2022, 12, 31) -> 44926 | D5: 155 | J5: CURRENT AVAILABLE BALANCE: | K5: =K4 - (D27) -> 12248
A6: Flat rent | B6: BANGALORE | C6: =DATE(2023, 1, 1) -> 44927 | D6: 7500
A7: Arghya (Scooty) | B7: EMI | C7: =DATE(2023, 1, 1) -> 44927 | D7: 2350
A8: Arghya (EMI Chair) | B8: EMI | C8: =DATE(2023, 1, 1) -> 44927 | D8: 1925
A9: Personal | B9: PERSONAL | C9: =DATE(2022, 12, 31) -> 44926 | D9: 5000
A10: New Year Party | B10: SOCIAL | C10: =DATE(2022, 12, 31) -> 44926 | D10: 4885 | J10: EXPECTED AVAILABLE BALANCE: | K10: =K5 - D61 + D15 -> -1059
A11: UTI-SIP | B11: SAVINGS | C11: =DATE(2023, 1, 1) -> 44927 | D11: 2000
A12: SAVINGS | B12: SAVINGS | C12: =DATE(2023, 1, 1) -> 44927 | D12: 10000
A13: SIP | B13: SAVINGS | C13: =DATE(2023, 1, 1) -> 44927 | D13: 3000
A14: SIP-KAKA | B14: TEMP | C14: =DATE(2023, 1, 1) -> 44927 | D14: 2500
A15: New Year Party | B15: TEMP | C15: =DATE(2023, 1, 1) -> 44927 | D15: 4500
A16: Barasat Matrimony | B16: SUBSCRIPTION | C16: =DATE(2022, 12, 31) -> 44926 | D16: 551
A17: MAA | B17: EMI | D17: 12000
A18: Cook | B18: FAMILY | D18: 1000
A19: Fridge EMI | B19: EMI | D19: 2386
C27: TOTAL EXPENSE | D27: =SUM(D3:D25) -> 68216
A31: PENDING
A32: PAYMENT REASON | B32: PAYMENT CATEGORY | D32: PAYMENT AMOUNT
A33: Flat electricity | B33: BANGALORE | D33: 200
A34: MOBILE RECHARGE | B34: BILL | D34: =762-(155) -> 607
A37: Personal | B37: PERSONAL | D37: 15000
A38: Technical Expenses | B38: PERSONAL | D38: 2000
C61: PENDING EXPENSE | D61: =SUM(D33:D59) -> 17807
A66: Kaka | B66: PENDING | D66: 30000

Sheet FEB23
A1: TOTAL EXPENSE LIST | J1: AVAILABLE FROM PREVIOUS MONTH: | K1: 8579
A2: PAYMENT REASON | B2: PAYMENT CATEGORY | C2: DATE | D2: PAYMENT AMOUNT | J2: INCOME IN CURRENT MONTH: | K2: 78014
A3: Flat rent | B3: BANGALORE | C3: =DATE(2023, 2, 1) -> 44958 | D3: 7500
A4: Arghya (EMI Scooty) | B4: EMI | C4: =DATE(2023, 2, 1) -> 44958 | D4: 2350 | J4: TOTAL AVAILABLE: | K4: =K1 + K2 + K3 -> 86593
A5: Arghya (EMI Chair) | B5: EMI | C5: =DATE(2023, 2, 1) -> 44958 | D5: 1925 | J5: CURRENT AVAILABLE BALANCE: | K5: =K4 - (D27) -> 32759
A6: Arghya (EMI Friedge) | B6: EMI | C6: =DATE(2023, 2, 1) -> 44958 | D6: 1958
A7: Web Server | B7: TECHNICAL | C7: =DATE(2023, 2, 1) -> 44958 | D7: 1000
A8: Mobile (EMI) | B8: EMI | C8: =DATE(2023, 2, 1) -> 44958 | D8: 3278
A9: Electricity | B9: FAMILY | C9: =DATE(2023, 2, 1) -> 44958 | D9: 3078
A10: UTI-SIP | B10: SAVINGS | C10: =DATE(2023, 2, 1) -> 44958 | D10: 2000 | J10: EXPECTED AVAILABLE BALANCE: | K10: =K5 - D61 -> 26974
A11: MAA | B11: EMI | C11: =DATE(2023, 2, 1) -> 44958 | D11: 12000
A12: Cook | B12: FAMILY | C12: =DATE(2023, 2, 1) -> 44958 | D12: 1000
A13: SIP | B13: SAVINGS | C13: =DATE(2023, 2, 1) -> 44958 | D13: 3000
A14: SIP-KAKA | B14: TEMP | C14: =DATE(2023, 2, 1) -> 44958 | D14: 2500
A15: SAVINGS | B15: SAVINGS | C15: =DATE(2023, 2, 1) -> 44958 | D15: 10000
A16: WiFi | B16: PERSONAL | C16: =DATE(2023, 1, 28) -> 44954 | D16: 1180
A17: Mobile recharge | B17: BILL | C17: =DATE(2023, 2, 1) -> 44958 | D17: =155 * 3 -> 465
A18: UCO Bank | B18: EMI | C18: =DATE(2023, 1, 28) -> 44954 | D18: 500
A19: Water | B19: WATER | C19: =DATE(2023, 1, 29) -> 44955 | D19: 100
C27: TOTAL EXPENSE | D27: =SUM(D3:D25) -> 53834
A31: PENDING
A32: PAYMENT REASON | B32: PAYMENT CATEGORY | D32: PAYMENT AMOUNT
A33: Flat electricity | B33: BANGALORE | D33: 500
A35: MOBILE RECHARGE | B35: BILL | D35: =750 - D17 -> 285
A36: Personal | B36: PERSONAL | D36: 5000
H44: =SUM(D4:D42) -> 105953
H45: =D7 + SUM(D4:D6) -> 7233
C61: PENDING EXPENSE | D61: =SUM(D33:D59) -> 5785
A66: Kaka | B66: PENDING | D66: 30000

Sheet MAR23
A1: TOTAL EXPENSE LIST | J1: AVAILABLE FROM PREVIOUS MONTH: | K1: 15652
A2: PAYMENT REASON | B2: PAYMENT CATEGORY | C2: DATE | D2: PAYMENT AMOUNT | J2: INCOME IN CURRENT MONTH: | K2: 99389
A3: SIP | B3: SAVINGS | C3: =DATE(2023, 2, 28) -> 44985 | D3: 3000
A4: SIP-KAKA | B4: TEMP | C4: =DATE(2023, 2, 28) -> 44985 | D4: 2500 | J4: TOTAL AVAILABLE: | K4: =K1 + K2 + K3 -> 115041
A5: Personal | B5: PERSONAL | C5: =DATE(2023, 2, 28) -> 44985 | D5: 5000 | J5: CURRENT AVAILABLE BALANCE: | K5: =K4 - (D27) -> 18423
A6: SAVINGS | B6: SAVINGS | C6: =DATE(2023, 2, 28) -> 44985 | D6: 23000
A7: Electricity | B7: FAMILY | C7: =DATE(2023, 2, 28) -> 44985 | D7: 3077
A8: UTI-SIP | B8: SAVINGS | C8: =DATE(2023, 2, 28) -> 44985 | D8: 2000
A9: Flat rent | B9: BANGALORE | C9: =DATE(2023, 2, 28) -> 44985 | D9: 7500
A10: Arghya (EMI Chair) | B10: EMI | C10: =DATE(2023, 2, 28) -> 44985 | D10: 1925 | J10: EXPECTED AVAILABLE BALANCE: | K10: =K5 - D61 -> -96597
A11: Arghya (EMI Friedge) | B11: EMI | C11: =DATE(2023, 2, 28) -> 44985 | D11: 1958
A12: Web Server | B12: TECHNICAL | C12: =DATE(2023, 2, 28) -> 44985 | D12: 2000
A13: Mobile (EMI) | B13: EMI | C13: =DATE(2023, 2, 28) -> 44985 | D13: 3280
A14: Mobile Recharge(7908760756) | B14: BILL | C14: =DATE(2023, 2, 28) -> 44985 | D14: 155
A15: CC Bill (AXIS) | B15: CC | C15: =DATE(2023, 3, 1) -> 44986 | D15: 10933
A16: CC Bill (SBI) | B16: CC | C16: =DATE(2023, 3, 1) -> 44986 | D16: 11888
A17: MOBILE RECHARGE | B17: BILL | C17: online | D17: =700 - (155 * 1) -> 545
A18: MAA | B18: EMI | C18: cash | D18: 15000
A19: Cook | B19: FAMILY | C19: cash | D19: 1000
A20: UCO Bank | B20: EMI | C20: online | D20: 500
A21: WiFi | B21: PERSONAL | C21: online | D21: 1357
C27: TOTAL EXPENSE | D27: =SUM(D3:D25) -> 96618
A31: PENDING
A32: PAYMENT REASON | B32: PAYMENT CATEGORY | D32: PAYMENT AMOUNT
C61: PENDING EXPENSE | D61: =SUM(D17:D58) -> 115020
A66: Kaka | B66: PENDING | D66: 30000

Sheet APR23
A1: TOTAL EXPENSE LIST | K1: AVAILABLE FROM PREVIOUS MONTH: | L1: 889
A2: PAYMENT REASON | B2: PAYMENT CATEGORY | C2: DATE | D2: PAYMENT AMOUNT | K2: INCOME IN CURRENT MONTH: | L2: =(76709 + 1357 + 7000) -> 85066
A3: CC Bill (AXIS) | B3: CC | C3: =DATE(2023, 3, 30) -> 45015 | D3: 3115
A4: Electricity | B4: FAMILY | C4: =DATE(2023, 3, 30) -> 45015 | D4: 3077 | K4: TOTAL AVAILABLE: | L4: =L1 + L2 + L3 -> 85955
A5: Flat rent | B5: BANGALORE | C5: =DATE(2023, 3, 30) -> 45015 | D5: 7500 | K5: CURRENT AVAILABLE BALANCE: | L5: =L4 - (D27) -> 5696
A6: Arghya (EMI Friedge) | B6: EMI | C6: =DATE(2023, 3, 30) -> 45015 | D6: 1960
A7: SIP | B7: SAVINGS | C7: =DATE(2023, 3, 30) -> 45015 | D7: 3000
A8: Kaka | B8: Temp | D8: 0
A9: SAVINGS | B9: SAVINGS | C9: =DATE(2023, 3, 30) -> 45015 | D9: 15000
A10: UTI-SIP | B10: SAVINGS | C10: =DATE(2023, 3, 30) -> 45015 | D10: 2000 | K10: EXPECTED AVAILABLE BALANCE: | L10: =L5 - D61 -> 4151
A11: Personal | B11: PERSONAL | C11: =DATE(2023, 3, 30) -> 45015 | D11: 1500
A12: MAA | B12: EMI | C12: =DATE(2023, 4, 2) -> 45018 | D12: 12000
A13: Cook | B13: FAMILY | C13: =DATE(2023, 4, 2) -> 45018 | D13: 1000 | K13: Savings | L13: =(115000 - 75000) -> 40000
A14: UCO Bank | B14: EMI | C14: =DATE(2023, 4, 1) -> 45017 | D14: 500
A15: Mobile (EMI) | B15: EMI | C15: =DATE(2023, 4, 1) -> 45017 | D15: 3280
A16: Flight ticket EMI | B16: EMI | C16: =DATE(2023, 4, 1) -> 45017 | D16: 1265
A17: Doctor | B17: MEDICAL | C17: =DATE(2023, 4, 1) -> 45017 | D17: =(1000 + 1000 + 1000 + 1000 + 3500) -> 7500
A18: cash | B18: PERSONAL | C18: =DATE(2023, 4, 1) -> 45017 | D18: 1000
A19: WiFi | B19: PERSONAL | C19: =DATE(2023, 4, 9) -> 45025 | D19: 1357
A20: Mobile Recharge(8617414770) | B20: BILL | C20: =DATE(2023, 4, 10) -> 45026 | D20: 155
A21: marketting | B21: FAMILY | C21: =DATE(2023, 4, 13) -> 45029 | D21: 2000
A22: maa | D22: =(11000 + 1000) -> 12000
A23: Mislenious | D23: 50
A24: Cash | B24: PERSONAL | C24: =DATE(2023, 4, 2) -> 45018 | D24: 1000
C27: TOTAL EXPENSE | D27: =SUM(D3:D25) -> 80259
A31: PENDING
A32: PAYMENT REASON | B32: PAYMENT CATEGORY | D32: PAYMENT AMOUNT
A33: Personal | B33: PERSONAL | C33: online | D33: 1000
A34: MOBILE RECHARGE | B34: BILL | C34: online | D34: =(700 - D20) -> 545
C61: PENDING EXPENSE | D61: =SUM(D33:D58) -> 1545
A66: Kaka | B66: PENDING | D66: 30000

Sheet MAY23
A1: TOTAL EXPENSE LIST | K1: AVAILABLE FROM PREVIOUS MONTH: | L1: ='APR23'!L5 -> 5696
A2: PAYMENT REASON | B2: PAYMENT CATEGORY | C2: DATE | D2: PAYMENT AMOUNT | G2: Color Code | H2: Category | K2: INCOME IN CURRENT MONTH: | L2: =92401 + 1357 -> 93758
A3: MOBILE RECHARGE | B3: BILL | C3: =DATE(2023, 4, 27) -> 45043 | D3: 150 | H3: Bills
A4: CC Bill (AXIS) | B4: CC | C4: =DATE(2023, 4, 27) -> 45043 | D4: =(7018 + 242) -> 7260 | H4: Savings | K4: TOTAL AVAILABLE: | L4: =L1 + L2 -> 99454
A5: Electricity | B5: FAMILY | C5: =DATE(2023, 4, 27) -> 45043 | D5: 3909 | H5: Maa | K5: CURRENT AVAILABLE BALANCE: | L5: =L4 - D39 + D35 -> 12657.87
A6: SIP | B6: SAVINGS | C6: =DATE(2023, 4, 27) -> 45043 | D6: 3000 | H6: Personal
A7: SAVINGS | B7: SAVINGS | C7: =DATE(2023, 4, 27) -> 45043 | D7: 35000 | H7: TEMP
A8: UCO Bank | B8: EMI | C8: =DATE(2023, 4, 27) -> 45043 | D8: 500 | H8: UNPLANNED
A9: Flat rent | B9: BANGALORE | C9: =DATE(2023, 4, 29) -> 45045 | D9: 8500
A10: Arghya (EMI Friedge) | B10: EMI | C10: =DATE(2023, 4, 29) -> 45045 | D10: 1960 | K10: EXPECTED AVAILABLE BALANCE: | L10: =L5 - D51 + (SUMIFS(D3:D32, B3:B32, "=TEMP")) -> 9672.87
A11: UTI-SIP | B11: SAVINGS | C11: =DATE(2023, 4, 29) -> 45045 | D11: 2000
A12: Clz trip | B12: PERSONAL | C12: =DATE(2023, 5,1) -> 45047 | D12: 3000
A13: MAA | B13: EMI | C13: =DATE(2023, 5,2) -> 45048 | D13: 5000
A14: Cook | B14: FAMILY | C14: =DATE(2023, 5,2) -> 45048 | D14: 1000 | K14: SAVINGS | L14: =(40000 - 20000 + D7) -> 55000
A15: MAA | B15: EMI | C15: =DATE(2023, 5,2) -> 45048 | D15: 1000
A16: Mobile Recharge (7908760756) | B16: BILL | C16: =DATE(2023, 5,2) -> 45048 | D16: 155
A17: GCETTB medical donation | B17: SOCIAL | C17: =DATE(2023, 5,2) -> 45048 | D17: 1000
A18: Mobile (EMI) | B18: EMI | C18: =DATE(2023, 5,4) -> 45050 | D18: 3280
A19: Flight ticket [KAKA] (EMI) | B19: EMI | C19: =DATE(2023, 5,4) -> 45050 | D19: =1265+270 -> 1535
A20: Train Ticket | B20: PERSONAL | C20: =DATE(2023, 5,8) -> 45054 | D20: =(77.15 + 88.6) -> 165.75
A21: Cash | B21: PERSONAL | C21: =DATE(2023, 5,4) -> 45050 | D21: 2000
A22: Mobile recharge (baba jio) | B22: BILL | D22: 155
A23: WiFi | B23: PERSONAL | C23: =DATE(2023, 5,11) -> 45057 | D23: 1357
A24: PMJJBY RENEWAL | B24: MISLENIOUS | C24: =DATE(2023, 5,8) -> 45054 | D24: 436
A25: Train Ticket | C25: =DATE(2023, 5,8) -> 45054 | D25: 77
A26: Clz Fest Contribution | B26: SOCIAL | C26: =DATE(2023, 5,15) -> 45061 | D26: 1000
A27: Bangalore WiFi | B27: BILL | C27: =DATE(2023, 5,15) -> 45061 | D27: 228.38
A28: Mobile recharge (Maa airtel) | B28: BILL | C28: =DATE(2023, 5,15) -> 45061 | D28: 155
A29: Gas | B29: BANGALORE | C29: =DATE(2023, 5,23) -> 45069 | D29: 600
A30: Water | B30: BANGALORE | C30: =DATE(2023, 5,21) -> 45067 | D30: 100
A31: WiFi | B31: PERSONAL | C31: =DATE(2023, 5,21) -> 45067 | D31: 236
A32: FoodBook recharge | B32: PERSONAL | C32: =DATE(2023, 5,22) -> 45068 | D32: 500
A33: Mobile recharge (3) | B33: BILL | D33: =(155 * 3) -> 465
A34: PayTm | B34: PERSONAL | C34: =DATE(2023, 5,26) -> 45072 | D34: 2000
A35: Inverse payment | D35: 928
C39: TOTAL EXPENSE | D39: =SUM(D3:D34) -> 87724.13
A43: PENDING
A44: PAYMENT REASON | B44: PAYMENT CATEGORY | D44: PAYMENT AMOUNT
A45: MOBILE RECHARGE | B45: BILL | C45: online | D45: =(800 - (D3 + D16 + D22 + D28)) -> 185
E46: =SUM(D45) -> 185
...

Sheet JUN23
A1: TOTAL EXPENSE LIST | K1: AVAILABLE FROM PREVIOUS MONTH: | L1: ='MAY23'!L5 -> 12657.87
A2: PAYMENT REASON | B2: PAYMENT CATEGORY | C2: DATE | D2: PAYMENT AMOUNT | G2: Color Code | H2: Category | K2: INCOME IN CURRENT MONTH: | L2: 96120
A3: CC Bill (AXIS) | B3: CC | C3: =DATE(2023, 5, 30) -> 45076 | D3: =(7810 + 2693) -> 10503 | H3: Bills | K3: Interest | L3: 128
A4: Electricity | B4: FAMILY | C4: =DATE(2023, 5, 31) -> 45077 | D4: 3909 | H4: Savings | K4: TOTAL AVAILABLE: | L4: =L1 + L2 + L3 -> 108905.87
A5: Flat rent | B5: BANGALORE | C5: =DATE(2023, 5, 30) -> 45076 | D5: 8500 | H5: Maa | K5: CURRENT AVAILABLE BALANCE: | L5: =L4 - (D40) -> 8227.87
A6: Arghya (EMI Friedge) | B6: EMI | C6: =DATE(2023, 5, 30) -> 45076 | D6: 1960 | H6: Personal
A7: Flight ticket [KAKA] (EMI) | B7: EMI | C7: =DATE(2023, 6, 19) -> 45096 | D7: 1265 | H7: Temp
A8: SIP | B8: SAVINGS | C8: =DATE(2023, 5, 30) -> 45076 | D8: 3000
A9: UTI-SIP | B9: SAVINGS | C9: =DATE(2023, 5, 30) -> 45076 | D9: 2000
A10: Mobile recharge(Maa Jio) | B10: BILL | C10: =DATE(2023, 5, 30) -> 45076 | D10: 155 | K10: EXPECTED AVAILABLE BALANCE: | L10: =L5 - D64 + (SUMIFS(D3:D25, B3:B25, "=TEMP")) -> 4210.87
A11: Medical Support | B11: SAVINGS | C11: =DATE(2023, 5, 31) -> 45077 | D11: 2000
A12: SAVINGS | B12: SAVINGS | C12: =DATE(2023, 5, 31) -> 45077 | D12: 45000
A13: MAA | B13: EMI | C13: =DATE(2023, 5, 31) -> 45077 | D13: 10000
A14: Cook | B14: FAMILY | C14: =DATE(2023, 5, 31) -> 45077 | D14: 1000 | K14: SAVINGS | L14: =(40000 + D12) -> 85000
A15: UCO Bank | B15: EMI | C15: =DATE(2023, 5, 31) -> 45077 | D15: 500
A16: FoodBook recharge | B16: PERSONAL | C16: =DATE(2023, 6, 1) -> 45078 | D16: 1000
A17: paytm | B17: PERSONAL | C17: =DATE(2023, 6, 2) -> 45079 | D17: 2000
A18: Paytm PostPaid recharge | B18: BILL | C18: =DATE(2023, 6, 4) -> 45081 | D18: 840
A19: Paytm | B19: PERSONAL | C19: =DATE(2023, 6, 6) -> 45083 | D19: 1000
A20: Mobile recharge(Baba Jio) | B20: BILL | C20: =DATE(2023, 6, 5) -> 45082 | D20: 155
A21: WiFi | B21: BILL | C21: =DATE(2023, 6, 8) -> 45085 | D21: 1357
A22: Mobile recharge(Airtel) | B22: BILL | C22: =DATE(2023, 6, 14) -> 45091 | D22: 155
A23: Mobile recharge(Maa Airtel) | B23: BILL | C23: =DATE(2023, 6, 10) -> 45087 | D23: 155
A24: Water | B24: PERSONAL | C24: =DATE(2023, 6, 14) -> 45091 | D24: 100
A25: Grocery | B25: PERSONAL | C25: =DATE(2023, 6, 14) -> 45091 | D25: 843
A26: WiFi (Airtel) | B26: BILL | C26: =DATE(2023, 6, 18) -> 45095 | D26: 1088
A27: Mobile recharge(Jio) | B27: BILL | C27: =DATE(2023, 6, 14) -> 45091 | D27: 155
A28: Mobile recharge(Rini) | B28: BILL | C28: =DATE(2023, 6, 14) -> 45091 | D28: 155
A29: Electricity | B29: BILL | C29: =DATE(2023, 6, 19) -> 45096 | D29: 583
A30: Paytm | B30: PERSONAL | C30: =DATE(2023, 6, 27) -> 45104 | D30: 1300
C40: TOTAL EXPENSE | D40: =SUM(D3:D30) -> 100678
A46: PENDING
A47: PAYMENT REASON | B47: PAYMENT CATEGORY | D47: PAYMENT AMOUNT
E50: =SUM(D48:D50) -> 0
A52: SIP | B52: SAVINGS | C52: online | D52: 3000
A59: Personal | B59: PERSONAL | C59: online | D59: =(8000 - (D16 + D17 + D18 + D19 + D25 + D30)) -> 1017 | E59: =D59 -> 1017
C64: PENDING EXPENSE | D64: =SUM(D48:D62) -> 4017
A66: Kaka | B66: PENDING | D66: 30000

Sheet JUL23
A1: TOTAL EXPENSE LIST | K1: AVAILABLE FROM PREVIOUS MONTH: | L1: ='JUN23'!L5 -> 8227.87
A2: PAYMENT REASON | B2: PAYMENT CATEGORY | C2: DATE | D2: PAYMENT AMOUNT | G2: Color Code | H2: Category | K2: INCOME IN CURRENT MONTH: | L2: 92401
A3: Mobile recharge(Maa Jio) | B3: BILL | C3: =DATE(2023, 6, 30) -> 45107 | D3: 155 | E3: 1 | H3: Bills
A4: CC Bill (AXIS) | B4: CC | C4: =DATE(2023, 6, 30) -> 45107 | D4: 6662 | E4: 1 | H4: Savings | K4: TOTAL AVAILABLE: | L4: =L1 + L2 -> 100628.87
A5: CC Bill (SBI) | B5: CC | C5: =DATE(2023, 6, 30) -> 45107 | D5: 8763 | E5: 1 | H5: Maa | K5: CURRENT AVAILABLE BALANCE: | L5: =L4 - (D32) -> 11728.87
A6: Electricity | B6: FAMILY | C6: =DATE(2023, 6, 30) -> 45107 | D6: 3909 | E6: 1 | H6: Personal
A7: Sagnik Marriage | B7: SOCIAL | C7: =DATE(2023, 6, 29) -> 45106 | D7: 1500 | E7: 1 | H7: Temp
A8: Sagnik Marriage | B8: TEMP | C8: =DATE(2023, 6, 29) -> 45106 | D8: =(3698 - 1500) -> 2198 | E8: 2
A9: Home Work | B9: SAVINGS | C9: online | D9: 40000 | E9: 1
A10: SIP | B10: SAVINGS | C10: online | D10: 3000 | E10: 1 | K10: EXPECTED AVAILABLE BALANCE: | L10: =L5 - D61 + (SUMIFS(D3:D30, B3:B30, "=TEMP")) -> -237.13
A11: UTI-SIP | B11: SAVINGS | C11: online | D11: 2000 | E11: 1
A12: MAA | B12: EMI | C12: cash | D12: 9000
A13: Cook | B13: FAMILY | C13: cash | D13: 1000
A14: Prem Birthday | B14: SOCIAL | D14: 500 | E14: 1 | K14: TEMP | L14: =(SUMIFS(D3:D30, B3:B30, "=TEMP")) -> 11237
A15: Prem Birthday | B15: TEMP | D15: 5110 | E15: 2
A16: Mobile recharge(Baba Jio) | B16: BILL | D16: 155 | E16: 1
A17: Water | B17: PERSONAL | D17: =100 + 100 -> 200
A18: SpicyTable | B18: PERSONAL | D18: 330
A19: SpicyTable (Rishi) | B19: TEMP | D19: 520
A20: SpicyTable (Arghya) | B20: TEMP | D20: 330
A21: KAKA SIP | B21: TEMP | D21: 2500 | E21: 2
A22: Chicken | B22: PERSONAL | D22: 140
A23: Arghya TEMP | B23: TEMP | D23: =140+90+349 -> 579
A24: Dinner 1st Jul | B24: PERSONAL | D24: 349
C32: TOTAL EXPENSE | D32: =SUM(D3:D30) -> 88900
A35: PENDING
A36: PAYMENT REASON | B36: PAYMENT CATEGORY | D36: PAYMENT AMOUNT
A37: MOBILE RECHARGE | B37: BILL | C37: online | D37: =(800 - (D3 + D16)) -> 490
A38: Flight ticket [KAKA] (EMI) | B38: EMI | C38: online | D38: 1265
A39: WiFi | B39: PERSONAL | C39: online | D39: =(1357 + 1150) -> 2507
A43: Flat rent | B43: BANGALORE | C43: online | D43: 8500
A44: Arghya (EMI Friedge) | B44: EMI | C44: online | D44: 1960 | E44: =SUM(D37:D44) -> 14722
A46: BackUp | B46: SAVINGS | C46: online | D46: 2000
E49: =SUM(D10:D11) -> 5000
A53: UCO Bank | B53: EMI | C53: online | D53: 500 | E53: =SUM(D12:D53) -> 126835
A55: Personal | B55: PERSONAL | C55: online | D55: =7000 - (SUMIFS(D3:D25, B3:B25, "=PERSONAL")) -> 5981
E56: =D55 + D7 -> 7481
C61: PENDING EXPENSE | D61: =SUM(D37:D59) -> 23203
A66: Kaka | B66: PENDING | D66: 30000

Sheet AUG23
A1: TOTAL EXPENSE LIST | K1: AVAILABLE FROM PREVIOUS MONTH: | L1: 3313
A2: PAYMENT REASON | B2: PAYMENT CATEGORY | C2: DATE | D2: PAYMENT AMOUNT | G2: Color Code | H2: Category | K2: INCOME IN CURRENT MONTH: | L2: 196555
H3: Bills
A4: WiFi recharge (Bangalore) | B4: BILL | C4: =DATE(2023, 7, 29) -> 45136 | D4: 1179 | H4: Savings | K4: TOTAL AVAILABLE: | L4: =L1 + L2 -> 199868
A5: Flat rent | B5: BANGALORE | C5: =DATE(2023, 7, 29) -> 45136 | D5: 8500 | H5: Maa | K5: CURRENT AVAILABLE BALANCE: | L5: =L4 - (D42) -> 16904
A6: Arghya (EMI Friedge) | B6: EMI | C6: =DATE(2023, 7, 29) -> 45136 | D6: 1960 | H6: Personal
A7: T-Shirt | B7: PERSONAL | C7: =DATE(2023, 7, 28) -> 45135 | D7: 1000 | H7: Temp
A8: Food | B8: PERSONAL | D8: =(517 + 208 + 134 + 212) -> 1071
A9: Water | B9: BILL | D9: =(100+100) -> 200 | S9: EXPECTED AVAILABLE BALANCE: | T9: =L5 - D65 + (SUMIFS(D5:D25, B5:B25, "=TEMP")) -> 13124
A11: Grocerry | C11: =DATE(2023, 7, 28) -> 45135 | D11: 356
A12: Saving | C12: =DATE(2023, 7, 30) -> 45137 | D12: 2300
A13: ITR Payment | C13: =DATE(2023, 7, 30) -> 45137 | D13: 390
A14: CC Bill (AXIS) | B14: CC | C14: =DATE(2023, 7, 30) -> 45137 | D14: 2649 | K14: SAVINGS | L14: =(40000 + D29) -> 160000
A15: CC Bill (RBL) | B15: TEMP | C15: =DATE(2023, 7, 30) -> 45137 | D15: 3315
A16: Ice-Cream | B16: PERSONAL | C16: =DATE(2023, 7, 31) -> 45138 | D16: 676
A17: Flight ticket [KAKA] (EMI) | B17: EMI | C17: =DATE(2023, 7, 31) -> 45138 | D17: 1265
A18: SIP | B18: SAVINGS | C18: =DATE(2023, 7, 31) -> 45138 | D18: 3000
A19: Personal | B19: PERSONAL | C19: =DATE(2023, 7, 31) -> 45138 | D19: 5000
A20: ITR payment | B20: BILL | C20: =DATE(2023, 7, 31) -> 45138 | D20: 1500
A21: UCO Bank | B21: EMI | C21: =DATE(2023, 7, 31) -> 45138 | D21: 500
A22: MAA | B22: EMI | C22: =DATE(2023, 8, 2) -> 45140 | D22: 12000
A23: Cook | B23: FAMILY | C23: =DATE(2023, 8, 2) -> 45140 | D23: 1000
A24: Electricity | B24: FAMILY | C24: =DATE(2023, 8, 2) -> 45140 | D24: 5571
A25: UTI-SIP | B25: SAVINGS | C25: =DATE(2023, 8, 2) -> 45140 | D25: 2000
A26: Mobile recharge | B26: BILL | C26: =DATE(2023, 7, 31) -> 45138 | D26: =(155+155+155) -> 465
A27: Paytm PostPaid | B27: BILL | C27: =DATE(2023, 8, 2) -> 45140 | D27: 3067
A28: Donation | B28: SOCIAL | C28: =DATE(2023, 8, 3) -> 45141 | D28: 4000
A29: Barir Kaj | B29: FAMILY | C29: =DATE(2023, 8, 4) -> 45142 | D29: 120000
C42: TOTAL EXPENSE | D42: =SUM(D3:D40) -> 182964
A46: PENDING
A47: PAYMENT REASON | B47: PAYMENT CATEGORY | D47: PAYMENT AMOUNT
A48: MOBILE RECHARGE | B48: BILL | C48: online | D48: =(800 - (D26)) -> 335
A50: WiFi | B50: PERSONAL | C50: online | D50: =(1357 + 1150) -> 2507 | E50: =SUM(D48:D50) -> 2842
E52: =D29 -> 120000
A54: Personal | B54: PERSONAL | C54: online | D54: =12000 - (D7 + D8 + D19 + D16) -> 4253 | E54: =D54 -> 4253
C65: PENDING EXPENSE | D65: =SUM(D48:D62) -> 7095
A88: Kaka | B88: PENDING | D88: 30000

Sheet SEP23
A1: TOTAL EXPENSE LIST | K1: AVAILABLE FROM PREVIOUS MONTH: | L1: 1130
A2: PAYMENT REASON | B2: PAYMENT CATEGORY | C2: DATE | D2: PAYMENT AMOUNT | G2: Color Code | H2: Category | K2: INCOME IN CURRENT MONTH: | L2: =94405+1178 -> 95583
A3: CC Bill (AXIS) | B3: CC | C3: Online | D3: 6472 | H3: Bills & EMI
A4: Water | C4: Online | D4: =100+100+100 -> 300 | H4: Savings | K4: TOTAL AVAILABLE: | L4: =L1 + L2 -> 96713
A5: Personal | B5: PERSONAL | C5: Online | D5: 2000 | H5: Maa | K5: CURRENT AVAILABLE BALANCE: | L5: =L4 - (D42) -> 35452
A6: CC Bill (SBI) | B6: CC | C6: Online | D6: 3657 | H6: Personal | K6: EXPECTED AVAILABLE BALANCE: | L6: =L5 - D75 + (SUMIFS(D7:D59, B7:B59, "=TEMP")) -> 24072
A7: SIP Temp | B7: TEMP | C7: Online | D7: 2500 | H7: Temp
A8: CC Bill (RBL) | B8: TEMP | C8: Online | D8: 2919
A9: SIP | B9: SAVINGS | C9: Online | D9: 3000
A10: Electricity | B10: BILL | C10: Online | D10: 5572
A11: Arghya (EMI Friedge) | B11: EMI | C11: Online | D11: 1960
A12: Flat rent | B12: BANGALORE | C12: Online | D12: 8500
A13: FlipKart Postpaid Payment | D13: 2844
A14: Mobile recharge (BABA Jio) | D14: 155
A15: Movie | D15: 715
A16: UTI-SIP | B16: SAVINGS | C16: Online | D16: 2000
A17: MAA | B17: EMI | C17: Online | D17: 11000
A18: Cook | B18: FAMILY | C18: Online | D18: 1000
A19: Paytm PostPaid | B19: CC | C19: Online | D19: 4000
A20: WiFi | B20: BILL | C20: Online | D20: 1357
A21: UCO Bank | B21: EMI | C21: Online | D21: 500
A22: Jio recharge | D22: 310
A23: FoodBook | B23: PERSONAL | D23: 500
C42: TOTAL EXPENSE | D42: =SUM(D3:D40) -> 61261
A46: PENDING
A47: PAYMENT REASON | B47: PAYMENT CATEGORY | D47: PAYMENT AMOUNT
A48: MOBILE RECHARGE | B48: BILL | C48: Online | D48: 800
A49: Flight ticket [KAKA] (EMI) | B49: EMI | C49: Online | D49: 1265
A50: WiFi | B50: BILL | C50: Online | D50: =(1179) -> 1179
A57: Bari EMI | B57: EMI | C57: Online | D57: 5555
E58: =SUM(D48:D57) - (D8 + D7) -> 3380
A59: Personal | B59: PERSONAL | C59: Online | D59: =(10000 - (D5)) -> 8000 | E59: =D59 -> 8000
E62: =SUM(D21) -> 500
C75: PENDING EXPENSE | D75: =SUM(D48:D72) -> 16799
A88: Kaka | B88: PENDING | D88: 30000

Sheet OCT23
A1: TOTAL EXPENSE LIST | K1: AVAILABLE FROM PREVIOUS MONTH: | L1: 1130
A2: PAYMENT REASON | B2: PAYMENT CATEGORY | C2: DATE | D2: PAYMENT AMOUNT | G2: Color Code | H2: Category | K2: INCOME IN CURRENT MONTH: | L2: =94405+1178 -> 95583
A3: CC Bill (AXIS) | B3: CC | C3: Online | D3: 6472 | H3: Bills & EMI
A4: Water | C4: Online | D4: =100+100+100 -> 300 | H4: Savings | K4: TOTAL AVAILABLE: | L4: =L1 + L2 -> 96713
A5: Personal | B5: PERSONAL | C5: Online | D5: 2000 | H5: Maa | K5: CURRENT AVAILABLE BALANCE: | L5: =L4 - (D42) -> 35452
A6: CC Bill (SBI) | B6: CC | C6: Online | D6: 3657 | H6: Personal | K6: EXPECTED AVAILABLE BALANCE: | L6: =L5 - D75 + (SUMIFS(D7:D59, B7:B59, "=TEMP")) -> 24072
A7: SIP Temp | B7: TEMP | C7: Online | D7: 2500 | H7: Temp
A8: CC Bill (RBL) | B8: TEMP | C8: Online | D8: 2919
A9: SIP | B9: SAVINGS | C9: Online | D9: 3000
A10: Electricity | B10: BILL | C10: Online | D10: 5572
A11: Arghya (EMI Friedge) | B11: EMI | C11: Online | D11: 1960
A12: Flat rent | B12: BANGALORE | C12: Online | D12: 8500
A13: FlipKart Postpaid Payment | D13: 2844
A14: Mobile recharge (BABA Jio) | D14: 155
A15: Movie | D15: 715
A16: UTI-SIP | B16: SAVINGS | C16: Online | D16: 2000
A17: MAA | B17: EMI | C17: Online | D17: 11000
A18: Cook | B18: FAMILY | C18: Online | D18: 1000
A19: Paytm PostPaid | B19: CC | C19: Online | D19: 4000
A20: WiFi | B20: BILL | C20: Online | D20: 1357
A21: UCO Bank | B21: EMI | C21: Online | D21: 500
A22: Jio recharge | D22: 310
A23: FoodBook | B23: PERSONAL | D23: 500
C42: TOTAL EXPENSE | D42: =SUM(D3:D40) -> 61261
A46: PENDING
A47: PAYMENT REASON | B47: PAYMENT CATEGORY | D47: PAYMENT AMOUNT
A48: MOBILE RECHARGE | B48: BILL | C48: Online | D48: 800
A49: Flight ticket [KAKA] (EMI) | B49: EMI | C49: Online | D49: 1265
A50: WiFi | B50: BILL | C50: Online | D50: =(1179) -> 1179
A57: Bari EMI | B57: EMI | C57: Online | D57: 5555
E58: =SUM(D48:D57) - (D8 + D7) -> 3380
A59: Personal | B59: PERSONAL | C59: Online | D59: =(10000 - (D5)) -> 8000 | E59: =D59 -> 8000
E62: =SUM(D21) -> 500
C75: PENDING EXPENSE | D75: =SUM(D48:D72) -> 16799
A88: Kaka | B88: PENDING | D88: 30000

Sheet DEC23
A1: TOTAL EXPENSE LIST | K1: AVAILABLE FROM PREVIOUS MONTH: | L1: 1818
A2: PAYMENT REASON | B2: PAYMENT CATEGORY | C2: DATE | D2: PAYMENT AMOUNT | G2: Color Code | H2: Category | K2: INCOME IN CURRENT MONTH: | L2: =99865+1357+1357 -> 102579
A3: CC Bill (AXIS) | B3: CC | C3: =DATE(2023, 11, 29) -> 45259 | D3: 5252 | H3: Bills & EMI
A4: CC Bill (SBI) | B4: CC | C4: =DATE(2023, 11, 29) -> 45259 | D4: 1836 | H4: Savings | K4: TOTAL AVAILABLE: | L4: =L1 + L2 -> 104397
A5: Arghya (EMI Friedge) | B5: EMI | C5: =DATE(2023, 11, 29) -> 45259 | D5: 1960 | H5: Maa | K5: CURRENT AVAILABLE BALANCE: | L5: =L4 - (D44) -> 4568
A6: Flat rent | B6: BANGALORE | C6: =DATE(2023, 11, 29) -> 45259 | D6: 8500 | H6: Personal | K6: EXPECTED AVAILABLE BALANCE: | L6: =L5 - D67 + (SUMIFS(D8:D62, B8:B62, "=TEMP")) -> 4178
A7: UCO Bank | B7: EMI | C7: =DATE(2023, 11, 29) -> 45259 | D7: 500 | H7: Temp
A8: Electricity | B8: BILL | C8: =DATE(2023, 11, 29) -> 45259 | D8: 3276 | H8: Family
A9: CC Bill (RBL) | B9: FAMILY | C9: =DATE(2023, 11, 29) -> 45259 | D9: 2899 | K9: Cash | L9: =(1400+500) -> 1900
A10: SIP Temp | B10: FAMILY | C10: =DATE(2023, 11, 29) -> 45259 | D10: 2500
A11: SIP | B11: SAVINGS | C11: =DATE(2023, 11, 29) -> 45259 | D11: 3000
A12: Bappa Kaka | B12: FAMILY | C12: =DATE(2023, 11, 29) -> 45259 | D12: 25000
A13: UTI-SIP | B13: SAVINGS | C13: =DATE(2023, 11, 29) -> 45259 | D13: 2000
A14: Mobile recharge(8653640704) | B14: BILL | C14: =DATE(2023, 11, 29) -> 45259 | D14: 155
A15: Cook | B15: FAMILY | C15: =DATE(2023, 11, 30) -> 45260 | D15: 4000
A16: Maa | B16: Maa | C16: =DATE(2023, 11, 30) -> 45260 | D16: 1000
A17: Kali Pujo | B17: FAMILY | C17: =DATE(2023, 11, 30) -> 45260 | D17: 6000
A18: Cash | B18: FAMILY | C18: =DATE(2023, 11, 30) -> 45260 | D18: 5000 | H18: 9169
A19: Air Bed | B19: FAMILY | C19: =DATE(2023, 11, 30) -> 45260 | D19: 2500
A20: Ladder | B20: FAMILY | C20: =DATE(2023, 11, 30) -> 45260 | D20: 2850
A21: Medicine (tab + molysheet) | B21: FAMILY | C21: =DATE(2023, 12, 3) -> 45263 | D21: =335+400+150 -> 885
A22: WiFi | B22: BILL | C22: =DATE(2023, 12, 5) -> 45265 | D22: =(1357) -> 1357
A23: Rent Mojo | B23: FAMILY | C23: =DATE(2023, 12, 7) -> 45267 | D23: =(514+463) - 489 -> 488
A24: Mobile recharge(8918405876) | B24: BILL | C24: =DATE(2023, 12, 7) -> 45267 | D24: 395
A25: Rice | B25: FAMILY | D25: 2000
A26: Cash | B26: FAMILY | D26: 3000
A27: Kali Pujo | B27: FAMILY | C27: Online | D27: 1500
A28: Office Marriage | B28: SOCIAL | C28: =DATE(2023, 12, 15) -> 45275 | D28: 1000
A29: Cab | B29: FAMILY | C29: =DATE(2023, 12, 10) -> 45270 | D29: =(230+332) -> 562
A30: Misc | D30: =(200 + 350+450+50+120+52+112)-914 -> 420
A31: Kitchen Goods | B31: FAMILY | D31: 1300
A32: Techno India | D32: 2700
A33: Reunion | B33: SOCIAL | C33: =DATE(2023, 12, 23) -> 45283 | D33: 4000
A34: IceCream | B34: PERSONAL | C34: =DATE(2023, 12, 23) -> 45283 | D34: 190
A35: Mobile recharge(8653640704) | B35: BILL | C35: =DATE(2023, 12, 7) -> 45267 | D35: 155
A36: Kitchen Self | B36: FAMILY | C36: =DATE(2023, 12, 22) -> 45282 | D36: 330
A37: Light Bulb | B37: FAMILY | C37: =DATE(2023, 12, 25) -> 45285 | D37: 140
A38: WiFi | B38: BILL | C38: =DATE(2023, 12, 26) -> 45286 | D38: =(1179) -> 1179
C44: TOTAL EXPENSE | D44: =SUM(D3:D40) -> 99829
A50: PENDING
...

Sheet JAN-24
A1: TOTAL EXPENSE LIST | K1: AVAILABLE FROM PREVIOUS MONTH: | L1: ='DEC23'!L5 -> 4568
A2: PAYMENT REASON | B2: PAYMENT CATEGORY | C2: DATE | D2: PAYMENT AMOUNT | G2: Color Code | H2: Category | K2: INCOME IN CURRENT MONTH: | L2: 79971
A3: CC Bill (AXIS) | B3: CC | C3: Online | D3: 8663 | H3: Bills & EMI
A4: Electricity | B4: BILL | C4: Online | D4: 3276 | H4: Savings | K4: TOTAL AVAILABLE: | L4: =L1 + L2 -> 84539
A5: SIP Temp | B5: FAMILY | C5: Online | D5: 2500 | H5: Maa | K5: CURRENT AVAILABLE BALANCE: | L5: =L4 - (D32) -> 4200
A6: SIP | B6: SAVINGS | C6: Online | D6: 3000 | H6: Personal | K6: EXPECTED AVAILABLE BALANCE: | L6: =L5 - D68 + (SUMIFS(D14:D40, B14:B40, "=TEMP")) -> -2577
A7: MOBILE RECHARGE (Rini Jio) | B7: BILL | C7: Online | D7: 155 | H7: Temp
A8: Medicine | B8: FAMILY | C8: Online | D8: 175 | H8: Family
A9: Misc | B9: PERSONAL | C9: Online | D9: =(98 + 190 + 90 + 100 + 270) -> 748 | K9: Cash | L9: 2500
A10: Aya Registration | B10: FAMILY | C10: Online | D10: 250
A11: Ice cream | B11: PERSONAL | C11: Online | D11: 240
A12: CC Bill (SBI) | B12: CC | C12: Online | D12: 7740
A13: Interest received | B13: INCOME | C13: Online | D13: -11
A14: UTI-SIP | B14: SAVINGS | C14: Online | D14: 2000
A15: Flat rent | B15: BANGALORE | C15: Online | D15: 8500
A16: UCO Bank | B16: EMI | C16: Online | D16: 500
A17: CC Bill (RBL) | B17: FAMILY | C17: Online | D17: 2892
A18: Cook | B18: FAMILY | C18: Cash | D18: 4000
A19: MOBILE RECHARGE (Maa Airtel) | B19: BILL | C19: Online | D19: 155
A20: CC Bill (SBI) [Repeat] | B20: CC | C20: Online | D20: 7740
A21: WiFi | B21: BILL | C21: Online | D21: =(1357) -> 1357
A22: MOBILE RECHARGE (Rini Airtel) | B22: BILL | C22: Online | D22: 155
A23: PulseOxymeter + Oxygen | B23: FAMILY | C23: Online | D23: 1330
A24: Cash widrawl | B24: PERSONAL | C24: Cash | D24: 3300
A25: Train ticket | B25: PERSONAL | C25: Online | D25: 77
A26: MOBILE RECHARGE (Maa Airtel) | B26: BILL | C26: Online | D26: 155
A27: Rni mess charge | B27: FAMILY | C27: Online | D27: 5800
A28: Babu Kaka | B28: FAMILY | C28: Online | D28: 10000
A29: Others | D29: =(4285 + 1357) -> 5642
C32: TOTAL EXPENSE | D32: =SUM(D3:D30) -> 80339
A35: PENDING
A36: PAYMENT REASON | B36: PAYMENT CATEGORY | D36: PAYMENT AMOUNT
A37: MOBILE RECHARGE | B37: BILL | C37: Online | D37: =775 - (D7 + D19 + D22 + D26) -> 155
A39: Personal | B39: PERSONAL | C39: Online | D39: =4000-(D9 + D24) -> -48
A40: Damma | B40: FAMILY | C40: Cash | D40: =(8000 - D23) -> 6670
C68: PENDING EXPENSE | D68: =SUM(D37:D60) -> 6777
A71: Kaka | B71: PENDING | D71: 30000
A72: Bappa Kaka | B72: PENDING | D72: =(85000+9500)-('DEC23'!D12) -> 69500
A73: Babu Kaka | B73: PENDING | D73: 50000

Sheet FEB-24
A1: TOTAL EXPENSE LIST | K1: AVAILABLE FROM PREVIOUS MONTH: | L1: ='JAN-24'!L5 -> 4200
A2: PAYMENT REASON | B2: PAYMENT CATEGORY | C2: DATE | D2: PAYMENT AMOUNT | G2: Color Code | H2: Category | K2: INCOME IN CURRENT MONTH: | L2: =(92199+1357) -> 93556
A3: CC Bill (AXIS) | B3: CC | C3: Online | D3: 8303 | H3: Bills & EMI
A4: Round Fig Balance | B4: PERSONAL | C4: Online | D4: 200 | H4: Savings | K4: TOTAL AVAILABLE: | L4: =L1 + L2 -> 97756
A5: Electricity | B5: BILL | C5: Online | D5: 2873 | H5: Maa | K5: CURRENT AVAILABLE BALANCE: | L5: =L4 - (D32) -> 16477
A6: CC Bill (RBL) | B6: FAMILY | C6: Online | D6: 2884 | H6: Personal | K6: EXPECTED AVAILABLE BALANCE: | L6: =L5 - D68 + (SUMIFS(D14:D44, B14:B44, "=TEMP")) -> 10488
A7: UCO Bank | B7: EMI | C7: Online | D7: 500 | H7: Temp
A8: Flat rent | B8: BANGALORE | C8: Online | D8: 8500 | H8: Family
A9: SIP Temp | B9: FAMILY | C9: Online | D9: 2500 | K9: Cash | L9: 2500
A10: SIP | B10: SAVINGS | C10: Online | D10: 3000
A11: CC Bill (SBI) | B11: CC | C11: Online | D11: 571
A12: Cook | B12: FAMILY | C12: Cash | D12: 4000
A13: Maa | B13: Maa | C13: Cash | D13: 1000
A14: Cash | B14: FAMILY | C14: Cash | D14: 15000
A15: Prasenjit Kaka | C15: Online | D15: 15000
A16: WiFi | B16: BILL | C16: Online | D16: =(1357) -> 1357
A17: Dammar Kaj | B17: FAMILY | C17: Online | D17: =(1001 + 2240) -> 3241
A18: Mother's Hut | B18: FAMILY | C18: Online | D18: 620
A19: Table Cloth | D19: 730
A20: Mitali Studio | D20: =(500 + 1800) -> 2300
A21: DalPuri | D21: 200
A22: Bappa Kaka | D22: 8500
C32: TOTAL EXPENSE | D32: =SUM(D3:D30) -> 81279
A35: PENDING
A36: PAYMENT REASON | B36: PAYMENT CATEGORY | D36: PAYMENT AMOUNT
A37: MOBILE RECHARGE | B37: BILL | C37: Online | D37: 700
A38: Flight ticket [KAKA] (EMI) | B38: EMI | C38: Online | D38: =(1265 - 155) -> 1110
A39: WiFi | B39: BILL | C39: Online | D39: =(1179) -> 1179
A40: Personal | B40: PERSONAL | C40: Online | D40: 3000
C68: PENDING EXPENSE | D68: =SUM(D37:D60) -> 5989
A71: Kaka | B71: PENDING | D71: 30000
A72: Bappa Kaka | B72: PENDING | D72: =(85000+9500)-('DEC23'!D12) -> 69500
A73: Babu Kaka | B73: PENDING | D73: =(50000 - ('JAN-24'!D28)) -> 40000

Sheet MAR-24
A1: TOTAL EXPENSE LIST | K1: AVAILABLE FROM PREVIOUS MONTH: | L1: 5807
A2: PAYMENT REASON | B2: PAYMENT CATEGORY | C2: DATE | D2: PAYMENT AMOUNT | G2: Color Code | H2: Category | K2: INCOME IN CURRENT MONTH: | L2: =(131909 + 1357) -> 133266
A3: CC Bill (AXIS) | B3: CC | C3: Online | D3: 11713 | H3: Bills & EMI
A4: CC Bill (RBL) | B4: FAMILY | C4: Online | D4: 2877 | H4: Savings | K4: TOTAL AVAILABLE: | L4: =L1 + L2 -> 139073
A5: Invest | B5: SAVINGS | C5: Online | D5: 1500 | H5: Maa | K5: CURRENT AVAILABLE BALANCE: | L5: =L4 - (D47) -> 40787.5
A6: SIP Temp | B6: FAMILY | C6: Online | D6: 2500 | H6: Personal | K6: EXPECTED AVAILABLE BALANCE: | L6: =L5 - D68 + (SUMIFS(D14:D53, B14:B53, "=TEMP")) -> 21603.5
A7: SIP | B7: SAVINGS | C7: Online | D7: 5000 | H7: Temp
A8: Misc | B8: miscellaneous | C8: Online | D8: =(150 + 240 + 263.5 + 90 + 50 - 100) -> 693.5 | H8: Family
A9: UCO Bank | B9: EMI | C9: Online | D9: 500 | K9: Cash | L9: 2500
A10: Electricity | B10: BILL | C10: Online | D10: 2874
A11: Flat rent | B11: BANGALORE | C11: Online | D11: 8500
A12: Cook | B12: FAMILY | C12: Cash | D12: 4000
A13: Maa | B13: Maa | C13: Cash | D13: =(1000 + 2500) -> 3500 | L13: =SUM(9195+7069+4557)-3000-5000 -> 12821
A14: Train Ticket | B14: PERSONAL | C14: Online | D14: 78
A15: Mobile Recharge(8918405876) | B15: BILL | C15: Online | D15: 395 | L15: =SUM(L6+L13) -> 34424.5
A16: Mobile Recharge(KAKA) | B16: BILL | C16: Online | D16: =(179 + 29) -> 208
A17: Mobile Recharge(8653640704) | B17: BILL | C17: Online | D17: 155
A18: Medicine Shop | B18: FAMILY | C18: Online | D18: 770
A19: Temp SIP | B19: TEMP | C19: Online | D19: 5500
A20: CC Bill (SBI) | B20: CC | C20: Online | D20: 8344
A21: Kolkata trip | B21: FAMILY | C21: Online | D21: 2607
A22: Laptop | B22: FAMILY | C22: Online | D22: 13769
A23: Flight Ticket | B23: FAMILY | C23: Online | D23: 7000
A24: Mother's Hut | B24: FAMILY | C24: Online | D24: 945
A25: Office | B25: SOCIAL | C25: Online | D25: 500
A26: Wifi | B26: BILL | C26: Online | D26: 1357
A27: Bappa Kaka | B27: EMI | C27: Online | D27: 10000
A28: Cash | B28: PERSONAL | C28: Cash | D28: 2500
A29: Gift | B29: PERSONAL | C29: Online | D29: 500
C47: TOTAL EXPENSE | D47: =SUM(D3:D45) -> 98285.5
A50: PENDING
A51: PAYMENT REASON | B51: PAYMENT CATEGORY | D51: PAYMENT AMOUNT
A52: MOBILE RECHARGE | B52: BILL | C52: Online | D52: =(800 - SUM(D15)) -> 405
A53: WiFi | B53: BILL | C53: Online | D53: =(1179) -> 1179
A54: Personal | B54: PERSONAL | C54: Online | D54: =(10000-D28) -> 7500
A55: Family | B55: FAMILY | C55: Online | D55: 15000
A56: Sweets | B56: PERSONAL | C56: Online | D56: 600
C68: PENDING EXPENSE | D68: =SUM(D52:D60) -> 24684
A71: Kaka | B71: PENDING | D71: 30000
A72: Bappa Kaka | B72: PENDING | D72: =(85000+9500)-(('DEC23'!D12)+D27) -> 59500
...

